Workbook
Name ACformat: [1]source!$B$5:$D$5
Name address_line1: #REF!
Name address_line2: #REF!
Name Adminlevel: [1]source!$B$9:$D$9
Name Admintype: [1]source!$B$7:$D$7
Name adress_line2: #REF!
Name adress_line3: #REF!
Name Authapproval: [1]source!$B$17:$C$17
Name Authlimit: [1]source!$B$15:$C$15
Name Authmethod: [1]source!$B$13:$D$13
Name BankAccounts: #REF!
Name BankAccounts_2: #REF!
Name Banks: '[2]03.3 Banks'!#REF!
Name Banks_2: '[3]03.3 Banks'!#REF!
Name Bena: [1]source!$B$19:$D$19
Name BIC: '[4]Client Information'!$E$5
Name BNPPBU: '[4]Client Information'!$E$14
Name BNPPinCOI: '[4]Client Information'!$E$24
Name BRinNotCOI: '[4]Client Information'!#REF!
Name BRinNOTCOI_2: '[5]Client Information'!#REF!
Name CalculatedRiskLevel: [4]Scoring!$F$65
Name cdvf: #REF!
Name checksum: [6]source!$B$21:$E$21
Name city: #REF!
Name city_2: #REF!
Name ClientName: '[4]Client Information'!$E$4
Name ClientSegment: '[4]Client Information'!$E$13
Name COIisBNPPRetail: '[4]Client Information'!#REF!
Name COlisBNPPRetail_2: '[5]Client Information'!#REF!
Name Companies: #REF!
Name Companies_2: #REF!
Name company_id: #REF!
Name company_id_2: #REF!
Name company_name: #REF!
Name company_name_2: #REF!
Name Country: #REF!
Name country_code: #REF!
Name country_code_2: #REF!
Name country_name: #REF!
Name country_name_2: #REF!
Name CountryOfBU: '[4]Client Information'!$E$15
Name CountryOfIncorporation: '[4]Client Information'!$E$23
Name Creditor: [6]source!$B$23:$D$23
Name critere_tri: #REF!
Name critere_tri_2: #REF!
Name CurrencyCode: [7]Currency!$B$4:$B$210
Name d: #REF!
Name d_2: #REF!
Name Data: #REF!
Name Data_: '[8]4 Accounts'!#REF!
Name Data_2: #REF!
Name Data_3: '[9]4 Accounts'!#REF!
Name ddd: #REF!
Name debut_tableau: #REF!
Name debut_tableau_2: #REF!
Name DEBUTUSER: #REF!
Name DEBUTUSER_DET: #REF!
Name dfg: #REF!
Name Doctype: [1]source!$B$1:$D$1
Name Documentation_LOV: [10]LOV!$G$2:$G$12

Sheet Sched 2.1 Software
A1: DIRECT CONNECTIVITY - API SCHEDULE 2.1 - Software
A5: ='Sched 3. Tech Params & Contacts'!A5 -> Participating User: | B5: ='Sched 3. Tech Params & Contacts'!B5 -> CPSP BELGIË NV | E5: ='Sched 3. Tech Params & Contacts'!E5 -> Internal SGI: | F5: ='Sched 3. Tech Params & Contacts'!F5 -> 02468 - TBD
A6: ='Sched 3. Tech Params & Contacts'!A6 -> Client type: | B6: ='Sched 3. Tech Params & Contacts'!B6 -> Establishement Institutions | E6: ='Sched 3. Tech Params & Contacts'!E6 -> RMPM: | F6: ='Sched 3. Tech Params & Contacts'!F6 -> 4AAP510785
A7: ='Sched 3. Tech Params & Contacts'!A7 -> Country: | B7: ='Sched 3. Tech Params & Contacts'!B7 -> Belgium | E7: ='Sched 3. Tech Params & Contacts'!E7 -> WF / ID: | F7: ='Sched 3. Tech Params & Contacts'!F7 -> TBD
A8: ='Sched 3. Tech Params & Contacts'!A8 -> Connectivity Info: | B8: ='Sched 3. Tech Params & Contacts'!B8 -> API 4 Corporate | E8: ='Sched 3. Tech Params & Contacts'!E8 -> Contract version: | F8: ='Sched 3. Tech Params & Contacts'!F8 -> DCA Standard
A9: ='Sched 3. Tech Params & Contacts'!A9 -> Author: | B9: ='Sched 3. Tech Params & Contacts'!B9 -> Frédéric Dufond | E9: ='Sched 3. Tech Params & Contacts'!E9 -> Contracting Bank: | F9: ='Sched 3. Tech Params & Contacts'!F9 -> BNP PARIBAS FORTIS SA
A10: ='Sched 3. Tech Params & Contacts'!A10 -> Client RM/Global CACM : | B10: ='Sched 3. Tech Params & Contacts'!B10 -> Davy Vanwetswinkel | E10: ='Sched 3. Tech Params & Contacts'!E10 -> Last update: | F10: ='Sched 3. Tech Params & Contacts'!F10 -> 45847
A12: Description of API protocol Access to the Server and use of the Service (as mentioned in clause 4 of the Agreement), require the Participating User to be equipped with a relevant Software or web service for transferring messages over the Internet. The Bank accepts the following standard API (Application Programming Interface) protocol: BNPP’s payment initiation APIs are based on HTTP protocol and REST (Representational State Transfer) standard, with the use of TLS1.2 for encryption and cross-authentication between the Bank and the Participating User. Bank accepts the TLS1.2 certificates solely delivered by the CAB forum members: https://cabforum.org/members/ Client identification and authentication is enhanced by a client ID and client secret exchange mechanism during the OAUTH2 access token process.

Sheet Sched 2.2 Signature & Comm
B2: DIRECT CONNECTIVITY - API SCHEDULE 2.2 - Digital signature solution & communication
B6: ='Sched 3. Tech Params & Contacts'!A5 -> Participating User: | C6: ='Sched 3. Tech Params & Contacts'!B5 -> CPSP BELGIË NV | F6: ='Sched 3. Tech Params & Contacts'!E5 -> Internal SGI: | G6: ='Sched 3. Tech Params & Contacts'!F5 -> 02468 - TBD
B7: ='Sched 3. Tech Params & Contacts'!A6 -> Client type: | C7: ='Sched 3. Tech Params & Contacts'!B6 -> Establishement Institutions | F7: ='Sched 3. Tech Params & Contacts'!E6 -> RMPM: | G7: ='Sched 3. Tech Params & Contacts'!F6 -> 4AAP510785
B8: ='Sched 3. Tech Params & Contacts'!A7 -> Country: | C8: ='Sched 3. Tech Params & Contacts'!B7 -> Belgium | F8: ='Sched 3. Tech Params & Contacts'!E7 -> WF / ID: | G8: ='Sched 3. Tech Params & Contacts'!F7 -> TBD
B9: ='Sched 3. Tech Params & Contacts'!A8 -> Connectivity Info: | C9: ='Sched 3. Tech Params & Contacts'!B8 -> API 4 Corporate | F9: ='Sched 3. Tech Params & Contacts'!E8 -> Contract version: | G9: ='Sched 3. Tech Params & Contacts'!F8 -> DCA Standard
B10: ='Sched 3. Tech Params & Contacts'!A9 -> Author: | C10: ='Sched 3. Tech Params & Contacts'!B9 -> Frédéric Dufond | F10: ='Sched 3. Tech Params & Contacts'!E9 -> Contracting Bank: | G10: ='Sched 3. Tech Params & Contacts'!F9 -> BNP PARIBAS FORTIS SA
B11: ='Sched 3. Tech Params & Contacts'!A10 -> Client RM/Global CACM : | C11: ='Sched 3. Tech Params & Contacts'!B10 -> Davy Vanwetswinkel | F11: ='Sched 3. Tech Params & Contacts'!E10 -> Last update: | G11: ='Sched 3. Tech Params & Contacts'!F10 -> 45847
B13: The use of the Service requires the Participating User to be equipped with a Digital Signature Solution. The Bank accepts the following Digital Signature Solution: 1. HTTP Signature (only for API channel) The way it should be implemented is the following: Computing a SHA256 digest of the HTTP body and adding this digest as an extra HTTP header as defined in [RFC3230] and [RFC5843]. Using your certificate in order to apply RSA-SHA256 signature on the digest Adding this signature within an extra HTTP header This HTTP signature mechanism is described more in detail in the API technical documentation provided during the implementation phase. 2. Certificates The Bank accepts the following certificates 3Skey provided by SWIFT: the 3SKEY solution, usable on the SWIFT network but also on proprietary networks or the Internet, allows corporates to sign financial messages and files sent to their banks, using a single signing device. eIDAS (electronique IDentification And trust Services for electronic transactions) certificates, provided by Trust Service Providers / Qualified Certificate Authorities. 3. Credentials and Certificates communication The transfer of sensitive data between the Bank and ithe Participating User regarding the certificates (TLS1.2 and Digital Signature) and the credentials for the OAUTH2 mechanism (client ID and client secret exchange mechanism) must be done solely via the secured web portal proposed by the Bank: https://securesharing.bnpparibas.com/workspace/sfs-itg/ The client secret exchange mechanism will be delivered by the Bank in an encrypted file on this portal. The password to decrypt this file will not be communicated via e-mail. The client must communicate a phone number to the Bank in order to recieve this password via SMS.

Sheet Sched 3. Tech Params & Contacts
A1: DIRECT CONNECTIVITY - API SCHEDULE 3 - Technical parameters & contacts
A5: Participating User: | B5: CPSP BELGIË NV | E5: Internal SGI: | F5: 02468 - TBD
A6: Client type: | B6: Establishement Institutions | E6: RMPM: | F6: 4AAP510785
A7: Country: | B7: Belgium | E7: WF / ID: | F7: TBD
A8: Connectivity Info: | B8: API 4 Corporate | E8: Contract version: | F8: DCA Standard
A9: Author: | B9: Frédéric Dufond | E9: Contracting Bank: | F9: BNP PARIBAS FORTIS SA
A10: Client RM/Global CACM : | B10: Davy Vanwetswinkel | E10: Last update: | F10: 45847
A11: The schedule have to be signed and sent back by post mail to: BNP PARIBAS - Domaine EBALD - ACI : CME05B1 - Valmy 2 - 33 – 41 Rue de Valmy - 93 100 MONTREUIL - France
A12: SCHEDULE SIGNATURE(S)
A13: Title First name & Last name | B13: [Signatory 1] | D13: Title First name & Last name | E13: [Signatory 2 if required]
A14: Function | B14: Function Signatory 1 | D14: Function | E14: Function Signatory 2
A17: Signature | B17: ________________________________________ | D17: Signature | E17: =B17 -> ________________________________________
A19: NOTIFICATIONS
A20: Notifications to be sent in accordance with clause 13 of this Agreement shall be addressed to the contact details indicated below:
A22: For the "Participating User": | B22: CPSP BELGIË NV | D22: For the "Bank": | E22: BNP Paribas Fortis SA
B23: Polstelsesteenweg 100 | E23: Montagne du Parc, 3
B24: 2400 MOL | E24: B-1000 Brussels
B25: Belgium | E25: BELGIUM
A26: 1/ Paramètres API
A27: In all cases, unless the Bank confirms otherwise with respect to a specific service or product, the parameters used are:
A28: Please see the technical parameters accepted by the Bank in the "API User Guide".
B30: Live environment | D30: Test environment
A31: Bank server | B31: api.cashmanagement.bnpparibas | D31: api.staging.cashmanagement.bnpparibas
A33: 2/ Client Environment
A35: Head of IT : | B35: [ To be filled in]
A36: Contact IT | B36: [ To be filled in]
A37: Contact IT Phone number: | B37: [ To be filled in]
A38: Contact IT e-mail: | B38: [ To be filled in]
A40: Customer Authentication Certificate | B40: [ To be filled in]
A41: Client IP address | B41: [ To be filled in]
A42: Authentication | B42: TLS 1.2
A44: TESTS
A45: Environment required for testing purposes | C45: TEST Environment: [YES/NO]
C46: LIVE Environment: [YES/NO]
A47: Date required for the starting of the test phase: | C47: ASAP
A48: Date required for the go live: | C48: ASAP
A50: Upon request, the companies may process API tests:
A51: • The tests will be run in test environment , after exchange of technical parameters
A52: • The tests will be run in the operational environment after signature of the DCA contract, as BNP Paribas offers a test mode
A54: CONTACTS
...

Sheet Sched 4. Account List & Serv
B4: DIRECT CONNECTIVITY - API SCHEDULE 4 - Account list & services
B8: Raison sociale client: | D8: ='Sched 3. Tech Params & Contacts'!$B5 -> CPSP BELGIË NV | J8: Ref. Interne SGI | K8: ='Sched 3. Tech Params & Contacts'!$F5 -> 02468 - TBD | U8: Legend regarding the updates:
B9: Client type | D9: ='Sched 3. Tech Params & Contacts'!$B6 -> Establishement Institutions | J9: RMPM | K9: ='Sched 3. Tech Params & Contacts'!$F6 -> 4AAP510785 | U9: =COUNTIF(B$32:B$55,"Unchanged (U)")&" account"&IF(COUNTIF(B$32:B$55,"U")>1,"s","")&" unchanged"& " (U)" -> 0 account unchanged (U)
B10: Pays: | D10: ='Sched 3. Tech Params & Contacts'!$B7 -> Belgium | J10: WF / ID | K10: ='Sched 3. Tech Params & Contacts'!$F7 -> TBD | U10: =COUNTIF(B$31:B$55,"Added (A)")&" account"&IF(COUNTIF(B$31:B$55,"A")>1,"s","")&" added"& " (A)" -> 22 account added (A)
B11: Info connectivité : | D11: ='Sched 3. Tech Params & Contacts'!$B8 -> API 4 Corporate | J11: Contract version | K11: ='Sched 3. Tech Params & Contacts'!$F8 -> DCA Standard | U11: =COUNTIF(B$32:B$55,"Suppressed (S)")&" account"&IF(COUNTIF(B$32:B$55,"R")>1,"s","")&" deleted"& " (S)" -> 0 account deleted (S)
B12: Auteur : | D12: ='Sched 3. Tech Params & Contacts'!$B9 -> Frédéric Dufond | J12: Banque contractante | K12: ='Sched 3. Tech Params & Contacts'!$F9 -> BNP PARIBAS FORTIS SA | U12: =COUNTIF(B$32:B$55,"Modified (M)")&" account"&IF(COUNTIF(B$32:B$55,"M")>1,"s","")&" modified"& " (M)" -> 0 account modified (M)
B13: Client RM/Global CACM : | D13: ='Sched 3. Tech Params & Contacts'!$B10 -> Davy Vanwetswinkel | J13: Mise à jour | K13: 45251
B14: ='Sched 3. Tech Params & Contacts'!A11 -> The schedule have to be signed and sent back by post mail to: BNP PARIBAS - Domaine EBALD - ACI : CME05B1 - Valmy 2 - 33 – 41 Rue de Valmy - 93 100 MONTREUIL - France
B16: SCHEDULE SIGNATURE(S) | K16: PAYMENTS | O16: STATUS | Q16: SERVICES | S16: REPORTING (3)
B17: ='Sched 3. Tech Params & Contacts'!A13 -> Title First name & Last name | E17: ='Sched 3. Tech Params & Contacts'!B13 -> [Signatory 1] | J17: Code NOP | K17: C30050 | L17: S40065 | M17: S40082 | O17: B90000 | Q17: C30100 | S17: /
B18: ='Sched 3. Tech Params & Contacts'!A14 -> Function | E18: ='Sched 3. Tech Params & Contacts'!B14 -> Function Signatory 1 | K18: SEND PAYMENT/COLLECTION INSTRUCTION | L18: SIGN SEPA PAYMENT TOWARDS THIRD PARTY | M18: SIGN INTERNATIONAL PAYMENT TOWARDS THIRD PARTY | O18: RECEIVE TRANSACTION STATUS | Q18: CHECK REACHABILITY | S18: LIST OF ACCOUNTS & LATEST BALANCES | T18: LATEST BALANCES FOR 1 ACCOUNT | U18: TOTAL DEBIT & CREDIT FOR 1 ACCOUNT PER DATE RANGE | V18: INTRADAYS FOR 1 ACCOUNT PER DATE RANGE | W18: TRANSACTIONS & BALANCE FOR 1 ACCOUNT PER DATE RANGE
B21: ='Sched 3. Tech Params & Contacts'!A17 -> Signature | E21: ='Sched 3. Tech Params & Contacts'!B17 -> ________________________________________
J23: Services:
B24: ='Sched 3. Tech Params & Contacts'!D13 -> Title First name & Last name | E24: ='Sched 3. Tech Params & Contacts'!E13 -> [Signatory 2 if required]
B25: ='Sched 3. Tech Params & Contacts'!D14 -> Function | E25: ='Sched 3. Tech Params & Contacts'!E14 -> Function Signatory 2
B28: ='Sched 3. Tech Params & Contacts'!D17 -> Signature | E28: ='Sched 3. Tech Params & Contacts'!E17 -> ________________________________________
J30: Formats: | K30: Json/XML (4) | O30: Json | Q30: Json | S30: Json | T30: Json | U30: Json | V30: Json | W30: Json
B31: Status | C31: Account Closed (1) | D31: Country | E31: Company | F31: RMPM | G31: Authority Letter | H31: Ccy | I31: BIC | J31: IBAN (2) | K31: C30050 | L31: S40065 | M31: S40065 | O31: B90000 | Q31: C30100 | X31: Limit per tranx
B32: Added (A) | C32: Non (N) | D32: BE | E32: CENTER PARCS ARDENNEN NV | F32: 4AAS425898 | G32: To do | H32: EUR | I32: DEGRBEBBXXX | J32: BE45845003189989 | S32: X | T32: X | U32: X | V32: X | W32: X | X32: n/a
B33: Added (A) | C33: Non (N) | D33: BE | E33: CENTER PARCS ARDENNEN NV | F33: 4AAS425898 | G33: To do | H33: EUR | I33: GEBABEBB36A | J33: BE82001258620668 | S33: X | T33: X | U33: X | V33: X | W33: X | X33: n/a
B34: Added (A) | C34: Non (N) | D34: BE | E34: CENTER PARCS ARDENNEN NV | F34: 4AAS425898 | G34: To do | H34: EUR | I34: GEBABEBB36A | J34: BE54001800261897 | S34: X | T34: X | U34: X | V34: X | W34: X | X34: n/a
B35: Added (A) | C35: Non (N) | D35: NL | E35: CENTER PARCS EUROPE BV | F35: 4AAH157307 | G35: To do | H35: EUR | I35: DEGRBEBBXXX | J35: BE04845003543031 | S35: X | T35: X | U35: X | V35: X | W35: X | X35: n/a
B36: Added (A) | C36: Non (N) | D36: NL | E36: CENTER PARCS EUROPE BV | F36: 4AAH157307 | G36: To do | H36: DKK | I36: FTSBDKKKXXX | J36: DK5681491700689015 | S36: X | T36: X | U36: X | V36: X | W36: X | X36: n/a
B37: Added (A) | C37: Non (N) | D37: NL | E37: CENTER PARCS EUROPE BV | F37: 4AAH157307 | G37: To do | H37: EUR | I37: GEBABEBB36A | J37: BE68001787412734 | S37: X | T37: X | U37: X | V37: X | W37: X | X37: n/a
B38: Added (A) | C38: Non (N) | D38: NL | E38: CENTER PARCS EUROPE BV | F38: 4AAH157307 | G38: To do | H38: DKK | I38: GEBABEBB36A | J38: BE68001787412734 | S38: X | T38: X | U38: X | V38: X | W38: X | X38: n/a
B39: Added (A) | C39: Non (N) | D39: NL | E39: CENTER PARCS EUROPE BV | F39: 4AAH157307 | G39: To do | H39: EUR | I39: GEBABEBB36A | J39: BE04001787412431 | S39: X | T39: X | U39: X | V39: X | W39: X | X39: n/a
B40: Added (A) | C40: Non (N) | D40: BE | E40: CPSP BELGIË NV | F40: 4AAP510785 | G40: Not Applicable | H40: EUR | I40: DEGRBEBBXXX | J40: BE60845003168670 | S40: X | T40: X | U40: X | V40: X | W40: X | X40: n/a
B41: Added (A) | C41: Non (N) | D41: BE | E41: CPSP BELGIË NV | F41: 4AAP510785 | G41: Not Applicable | H41: EUR | I41: GEBABEBB36A | J41: BE44001787452645 | S41: X | T41: X | U41: X | V41: X | W41: X | X41: n/a
B42: Added (A) | C42: Non (N) | D42: BE | E42: CPSP BELGIË NV | F42: 4AAP510785 | G42: Not Applicable | H42: EUR | I42: GEBABEBB36A | J42: BE59001787450726 | S42: X | T42: X | U42: X | V42: X | W42: X | X42: n/a
B43: Added (A) | C43: Non (N) | D43: BE | E43: CPSP BELGIË NV | F43: 4AAP510785 | G43: Not Applicable | H43: EUR | I43: GEBABEBB36A | J43: BE79001787451433 | S43: X | T43: X | U43: X | V43: X | W43: X | X43: n/a
... B53: Added (A) | C53: Non (N) | D53: BE | E53: TERHILLS VAKANTIEPARK NV | F53: 4ABC588356 | G53: To do | H53: EUR | I53: KREDBEBBXXX | J53: BE36744098745181 | S53: X | T53: X | U53: X | V53: X | W53: X | X53: n/a
B57: (1) To fill in if the statuts is "Suppressed (S)"
B58: (2) Populate the IBAN for Reporting
B59: (3) Nota Bene : Third party banks cannot be included in API Corporate channel
B60: (4) FCY: Foreign Currency

Sheet Sched 6. Fees & Payments
B1: DIRECT CONNECTIVITY - API SCHEDULE 6 - Fees & Payment
B5: ='Sched 3. Tech Params & Contacts'!A5 -> Participating User: | C5: ='Sched 3. Tech Params & Contacts'!B5 -> CPSP BELGIË NV | F5: ='Sched 3. Tech Params & Contacts'!E5 -> Internal SGI: | G5: ='Sched 3. Tech Params & Contacts'!F5 -> 02468 - TBD
B6: ='Sched 3. Tech Params & Contacts'!A6 -> Client type: | C6: ='Sched 3. Tech Params & Contacts'!B6 -> Establishement Institutions | F6: ='Sched 3. Tech Params & Contacts'!E6 -> RMPM: | G6: ='Sched 3. Tech Params & Contacts'!F6 -> 4AAP510785
B7: ='Sched 3. Tech Params & Contacts'!A7 -> Country: | C7: ='Sched 3. Tech Params & Contacts'!B7 -> Belgium | F7: ='Sched 3. Tech Params & Contacts'!E7 -> WF / ID: | G7: ='Sched 3. Tech Params & Contacts'!F7 -> TBD
B8: ='Sched 3. Tech Params & Contacts'!A8 -> Connectivity Info: | C8: ='Sched 3. Tech Params & Contacts'!B8 -> API 4 Corporate | F8: ='Sched 3. Tech Params & Contacts'!E8 -> Contract version: | G8: ='Sched 3. Tech Params & Contacts'!F8 -> DCA Standard
B9: ='Sched 3. Tech Params & Contacts'!A9 -> Author: | C9: ='Sched 3. Tech Params & Contacts'!B9 -> Frédéric Dufond | F9: ='Sched 3. Tech Params & Contacts'!E9 -> Contracting Bank: | G9: ='Sched 3. Tech Params & Contacts'!F9 -> BNP PARIBAS FORTIS SA
B10: ='Sched 3. Tech Params & Contacts'!A10 -> Client RM/Global CACM : | C10: ='Sched 3. Tech Params & Contacts'!B10 -> Davy Vanwetswinkel | F10: ='Sched 3. Tech Params & Contacts'!E10 -> Last update: | G10: ='Sched 3. Tech Params & Contacts'!F10 -> 45847
B12: SCHEDULE SIGNATURE(S)
B13: Title First name & Last name | C13: [Signatory 1] | E13: Title First name & Last name | F13: [Signatory 2 if required]
B14: Function | C14: Function Signatory 1 | E14: Function | F14: Function Signatory 2
B17: Signature | C17: ________________________________________ | E17: Signature | F17: =C17 -> ________________________________________
B22: Fees that are charged monthly shall be calculated for a whole calendar month irrespective of the day of the month on which the relevant Operating Account is registered with or removed from the Services. The Participating User authorises the Bank to debit its account directly (account details indicated below) and thus for the entire duration of the present Agreement. The fees shall be debited from the account indicated below designated during the month following the month in which the fees fall due. All fees and other payments payable by the Participating User to the Bank under this Agreement shall be made without any restriction, condition, set-off or counterclaim and shall be free and clear of any deduction or withholding on account of any tax or otherwise of whatsoever nature and howsoever arising (“Taxes”). In the event that any Taxes are required to be deducted or withheld from any payment payable by the Participating User to the Bank, such payment shall be increased by such amount so as to ensure that the net amount received and retained by the Bank will be the full amount which the Bank would have received had no such deduction or withholding been made or required.
B25: Branch Code:
B26: Bank code: | C26: GEBABEBB
B27: IBAN:
B29: Fees : | C29: Implementation fee (one off) | D29: 1.500 euro
C30: BNPP Group Accounts | D30: 20 EUR / month
C31: 3rd Bank Accounts | D31: 20 EUR / month
